Workbook

Sheet Lead Generation 
A1: Leads
A3: Customer Name | B3: Date Found | C3: Primary Contact | D3: Summary | E3: Customer Converted | F3: Contract Amount (Yearly) | H3: Total Leads
A4: Apex Manufacturing | B4: 46154 | C4: Sarah Jenkins | D4: Interested in packaging line automation and parts replacement. | E4: Yes | F4: 145000 | H4: =COUNT(F4:F69) -> 66
A5: Summit Logistics | B5: 46160 | C5: Marcus Vance | D5: Requested quote for fleet tracking hardware and IoT integration. | E5: No | F5: 82000
A6: Horizon Foods | B6: 46166 | C6: Elena Rostova | D6: Inquired about conveyer belt subassembly and spare parts catalog. | E6: Yes | F6: 210000
A7: Beacon BioTech | B7: 46175 | C7: David Chen | D7: Evaluating high-throughput sorting equipment for lab expansion. | E7: Yes | F7: 350000
A8: Vanguard Energy | B8: 46183 | C8: Rachel Adams | D8: Looking into predictive maintenance software for regional plants. | E8: No | F8: 65000
A9: Sterling Industrial | B9: 46188 | C9: James Miller | D9: Bulk order inquiry for custom replacement components and bearings. | E9: Yes | F9: 120000
A10: Nexus Robotics | B10: 46195 | C10: Amanda Taylor | D10: Reviewing cross-selling options for integrated robotic arms. | E10: Yes | F10: 480000
A11: Pioneer Packaging | B11: 46204 | C11: Robert Martinez | D11: Needs quote engine integration for aftermarket parts platform. | E11: No | F11: 95000
A12: Crestview Cold Storage | B12: 46212 | C12: Lisa Thompson | D12: Exploring automated palletizing solutions and sensors. | E12: Yes | F12: 275000
A13: Atlas Distribution | B13: 46219 | C13: Brian Wright | D13: Initial call regarding lifecycle service agreements and support. | E13: No | F13: 50000
A14: Quantum Dynamics | B14: 46231 | C14: Megan Foster | D14: Request for proposals on custom structural steel subassemblies. | E14: Yes | F14: 190000
A15: Midwest Processing | B15: 46239 | C15: Kevin O'Brien | D15: Scheduling demo for predictive demand forecasting dashboard. | E15: No | F15: 110000
A16: Pinnacle Automation | B16: 46246 | C16: Derek Vance | D16: Upgrading packaging sorter lines and conveyor belts. | E16: Yes | F16: 210000
... A69: Bay Area Tech Logistics | B69: 46626 | C69: Barbara Gordon | D69: Micro-fulfillment automated sorting system. | E69: Yes | F69: 510000

Sheet Assumptions  
A1: Customer and Revenue Assumptions
A2: Assumption | B2: Example | C2: Units
A3: Beginning customers | B3: 10 | C3: customers
A4: New customers Month 1 | B4: 2 | C4: customers
A5: Monthly churn | B5: 0.03 | C5: %
A6: Free → Paid conversion | B6: 0.1 | C6: %
A7: Trial period | B7: 14 | C7: days
A8: Weighted Average ARPU | B8: =(B12*C12)+(B13*C13)+(B14*C14) -> 14 | D8: for pricing tiers
A10: SAAS Pricing Assumptions
A11: Plan | B11: Price / Month | C11: % of Customers
A12: Trial | B12: 0 | C12: 0.6
A13: Pro | B13: 20 | C13: 0.3
A14: Enterprise | B14: 80 | C14: 0.1
A15: Customer Acquistion Assumptions
A16: Assumption | B16: Example
A17: Monthly marketing spend | B17: 100
A18: Leads Generated | B18: 50
A19: Lead → trial conversion | B19: 0.2
A20: Trial → paid conversion | B20: 0.05
A22: COGS Assumptions
A23: Cost | B23: Assumption
A24: Cloud hosting | B24: $5 / customer
A25: Payment processing | B25: 2.9% of revenue
A26: Third-party APIs - for customer support | B26: $1 / customer
A27: Other direct costs | B27: 1% of revenue
A28: Headcount Assumptions
A29: Employees not getting paid yet
A30: OPEX Assumptions
A31: Category | B31: Expense | C31: Example
A32: Sales & Marketing | B32: UGC / AI content | C32: $25/mo
B33: Events | C33: $0/mo
B34: Other S&M / demos | C34: $25/mo
A35: R&D | B35: Development software | C35: $25/mo
B36: Product tools | C36: $10/mo
B37: Contractors / interns | C37: $0/mo
A38: G&A | B38: Legal | C38: $25/mo
B39: Insurance | C39: $25/mo
B40: Liability Insurance | C40: $20/mo
B41: Cyber Insurance | C41: $25/mo
B42: Software / Workspace | C42: $20/mo
...

Sheet Financial Model 
N3: Total Customers
N4: =SUM(C28:Y28) -> 668
S7: Total EBIT
N9: Total Revenue | S9: =SUM(C56:Y56) -> 1456.992
N10: =SUM(C35:Y35) -> 9352
A18: Financial Model
B19: Line Item | C19: 46204 | D19: 46235 | E19: 46266 | F19: 46296 | G19: 46327 | H19: 46357 | I19: 46388 | J19: 46419 | K19: 46447 | L19: 46478 | M19: 46508 | N19: 46539 | O19: 46569 | P19: 46600 | Q19: 46631 | R19: 46661 | S19: 46692 | T19: 46722 | U19: 46753 | V19: 46784 | W19: 46813 | X19: 46844 | Y19: 46874
A20: Aquisition funnel | B20: Leads Generated - | C20: ='Lead Generation '!$H$4 -> 66 | D20: 125 | E20: 145 | F20: 150 | G20: 115 | H20: 200 | I20: 30 | J20: 50 | K20: 45 | L20: 43 | M20: 67 | N20: 867 | O20: 454 | P20: 2323 | Q20: 445 | R20: 65 | S20: 54 | T20: 76 | U20: 87 | V20: 45 | W20: 65 | X20: 76 | Y20: 54
B21: Lead $\to$ Trial Conversion | C21: ='Assumptions '!$B$19 -> 0.2 | D21: ='Assumptions '!$B$19 -> 0.2 | E21: ='Assumptions '!$B$19 -> 0.2 | F21: ='Assumptions '!$B$19 -> 0.2 | G21: ='Assumptions '!$B$19 -> 0.2 | H21: ='Assumptions '!$B$19 -> 0.2 | I21: ='Assumptions '!$B$19 -> 0.2 | J21: ='Assumptions '!$B$19 -> 0.2 | ... Y21: ='Assumptions '!$B$19 -> 0.2
B22: Trials Started | C22: =C20*C21 -> 13.2 | D22: =D20*D21 -> 25 | E22: =E20*E21 -> 29 | F22: =F20*F21 -> 30 | G22: =G20*G21 -> 23 | H22: =H20*H21 -> 40 | I22: =I20*I21 -> 6 | J22: =J20*J21 -> 10 | ... Y22: =Y20*Y21 -> 10.8
B23: Trial $\to$ Paid Conversion | C23: ='Assumptions '!$B$20 -> 0.05 | D23: ='Assumptions '!$B$20 -> 0.05 | E23: ='Assumptions '!$B$20 -> 0.05 | F23: ='Assumptions '!$B$20 -> 0.05 | G23: ='Assumptions '!$B$20 -> 0.05 | H23: ='Assumptions '!$B$20 -> 0.05 | I23: ='Assumptions '!$B$20 -> 0.05 | J23: ='Assumptions '!$B$20 -> 0.05 | ... Y23: ='Assumptions '!$B$20 -> 0.05
B24: New Paid Customers | C24: =ROUNDUP(C22*C23,0) -> 1 | D24: =ROUNDUP(D22*D23,0) -> 2 | E24: =ROUNDUP(E22*E23,0) -> 2 | F24: =ROUNDUP(F22*F23,0) -> 2 | G24: =ROUNDUP(G22*G23,0) -> 2 | H24: =ROUNDUP(H22*H23,0) -> 2 | I24: =ROUNDUP(I22*I23,0) -> 1 | J24: =ROUNDUP(J22*J23,0) -> 1 | ... Y24: =ROUNDUP(Y22*Y23,0) -> 1
A25: Customer Waterfall | B25: Beginning Active Customers | C25: ='Assumptions '!$B$3 -> 10 | D25: =C28 -> 9 | E25: =D28 -> 10 | F25: =E28 -> 11 | G25: =F28 -> 12 | H25: =G28 -> 13 | I25: =H28 -> 14 | J25: =I28 -> 14 | K25: =J28 -> 14 | ... Y25: =X28 -> 45
B26: Monthly Churn Rate | C26: ='Assumptions '!$B$5 -> 0.03 | D26: ='Assumptions '!$B$5 -> 0.03 | E26: ='Assumptions '!$B$5 -> 0.03 | F26: ='Assumptions '!$B$5 -> 0.03 | G26: ='Assumptions '!$B$5 -> 0.03 | H26: ='Assumptions '!$B$5 -> 0.03 | I26: ='Assumptions '!$B$5 -> 0.03 | J26: ='Assumptions '!$B$5 -> 0.03 | ... Y26: ='Assumptions '!$B$5 -> 0.03
B27: (-) Churned Customers | C27: =ROUNDUP(SUM(C25:C25)*C26, 0) -> 1 | D27: =ROUNDUP(SUM(D25:D25)*D26, 0) -> 1 | E27: =ROUNDUP(SUM(E25:E25)*E26, 0) -> 1 | F27: =ROUNDUP(SUM(F25:F25)*F26, 0) -> 1 | G27: =ROUNDUP(SUM(G25:G25)*G26, 0) -> 1 | H27: =ROUNDUP(SUM(H25:H25)*H26, 0) -> 1 | I27: =ROUNDUP(SUM(I25:I25)*I26, 0) -> 1 | J27: =ROUNDUP(SUM(J25:J25)*J26, 0) -> 1 | ... Y27: =ROUNDUP(SUM(Y25:Y25)*Y26, 0) -> 2
B28: Ending Active Customers | C28: =SUM(C25:C25)-C27 -> 9 | D28: =SUM(D24:D25)-D27 -> 10 | E28: =SUM(E24:E25)-E27 -> 11 | F28: =SUM(F24:F25)-F27 -> 12 | G28: =SUM(G24:G25)-G27 -> 13 | H28: =SUM(H24:H25)-H27 -> 14 | I28: =SUM(I24:I25)-I27 -> 14 | J28: =SUM(J24:J25)-J27 -> 14 | K28: =SUM(K24:K25)-K27 -> 14 | ... Y28: =SUM(Y24:Y25)-Y27 -> 44
A29: Customer Breakdown | B29: Trial Tier Customers | C29: =ROUND(C28*'Assumptions '!$C$12, 1) -> 5.4 | D29: =ROUND(D28*'Assumptions '!$C$12, 1) -> 6 | E29: =ROUND(E28*'Assumptions '!$C$12, 1) -> 6.6 | F29: =ROUND(F28*'Assumptions '!$C$12, 1) -> 7.2 | G29: =ROUND(G28*'Assumptions '!$C$12, 1) -> 7.8 | H29: =ROUND(H28*'Assumptions '!$C$12, 1) -> 8.4 | I29: =ROUND(I28*'Assumptions '!$C$12, 1) -> 8.4 | J29: =ROUND(J28*'Assumptions '!$C$12, 1) -> 8.4 | ... Y29: =ROUND(Y28*'Assumptions '!$C$12, 1) -> 26.4
B30: Pro Tier Customers | C30: =ROUND(C28*'Assumptions '!$C$13, 1) -> 2.7 | D30: =ROUND(D28*'Assumptions '!$C$13, 1) -> 3 | E30: =ROUND(E28*'Assumptions '!$C$13, 1) -> 3.3 | F30: =ROUND(F28*'Assumptions '!$C$13, 1) -> 3.6 | G30: =ROUND(G28*'Assumptions '!$C$13, 1) -> 3.9 | H30: =ROUND(H28*'Assumptions '!$C$13, 1) -> 4.2 | I30: =ROUND(I28*'Assumptions '!$C$13, 1) -> 4.2 | J30: =ROUND(J28*'Assumptions '!$C$13, 1) -> 4.2 | ... Y30: =ROUND(Y28*'Assumptions '!$C$13, 1) -> 13.2
B31: Enterprise Tier Customers | C31: =ROUND(C28*'Assumptions '!$C$14, 1) -> 0.9 | D31: =ROUND(D28*'Assumptions '!$C$14, 1) -> 1 | E31: =ROUND(E28*'Assumptions '!$C$14, 1) -> 1.1 | F31: =ROUND(F28*'Assumptions '!$C$14, 1) -> 1.2 | G31: =ROUND(G28*'Assumptions '!$C$14, 1) -> 1.3 | H31: =ROUND(H28*'Assumptions '!$C$14, 1) -> 1.4 | I31: =ROUND(I28*'Assumptions '!$C$14, 1) -> 1.4 | J31: =ROUND(J28*'Assumptions '!$C$14, 1) -> 1.4 | ... Y31: =ROUND(Y28*'Assumptions '!$C$14, 1) -> 4.4
A32: Revenue Build (MRR) | B32: Basic Plan Revenue | C32: ='Assumptions '!$B$12*C29 -> 0 | D32: ='Assumptions '!$B$12*D29 -> 0 | E32: ='Assumptions '!$B$12*E29 -> 0 | F32: ='Assumptions '!$B$12*F29 -> 0 | G32: ='Assumptions '!$B$12*G29 -> 0 | H32: ='Assumptions '!$B$12*H29 -> 0 | I32: ='Assumptions '!$B$12*I29 -> 0 | J32: ='Assumptions '!$B$12*J29 -> 0 | ... Y32: ='Assumptions '!$B$12*Y29 -> 0
B33: Pro Plan Revenue | C33: =C30*'Assumptions '!$B$13 -> 54 | D33: =D30*'Assumptions '!$B$13 -> 60 | E33: =E30*'Assumptions '!$B$13 -> 66 | F33: =F30*'Assumptions '!$B$13 -> 72 | G33: =G30*'Assumptions '!$B$13 -> 78 | H33: =H30*'Assumptions '!$B$13 -> 84 | I33: =I30*'Assumptions '!$B$13 -> 84 | J33: =J30*'Assumptions '!$B$13 -> 84 | ... Y33: =Y30*'Assumptions '!$B$13 -> 264
B34: Enterprise Plan Revenue | C34: ='Assumptions '!$B$14* 'Financial Model '!C31 -> 72 | D34: ='Assumptions '!$B$14* 'Financial Model '!D31 -> 80 | E34: ='Assumptions '!$B$14* 'Financial Model '!E31 -> 88 | F34: ='Assumptions '!$B$14* 'Financial Model '!F31 -> 96 | G34: ='Assumptions '!$B$14* 'Financial Model '!G31 -> 104 | H34: ='Assumptions '!$B$14* 'Financial Model '!H31 -> 112 | I34: ='Assumptions '!$B$14* 'Financial Model '!I31 -> 112 | J34: ='Assumptions '!$B$14* 'Financial Model '!J31 -> 112 | ... Y34: ='Assumptions '!$B$14* 'Financial Model '!Y31 -> 352
B35: Total MRR | C35: =SUM(C32:C34) -> 126 | D35: =SUM(D32:D34) -> 140 | E35: =SUM(E32:E34) -> 154 | F35: =SUM(F32:F34) -> 168 | G35: =SUM(G32:G34) -> 182 | H35: =SUM(H32:H34) -> 196 | I35: =SUM(I32:I34) -> 196 | J35: =SUM(J32:J34) -> 196 | ... Y35: =SUM(Y32:Y34) -> 616
A36: COGS | B36: Ending Active Customers | C36: =C28 -> 9 | D36: =D28 -> 10 | E36: =E28 -> 11 | F36: =F28 -> 12 | G36: =G28 -> 13 | H36: =H28 -> 14 | I36: =I28 -> 14 | J36: =J28 -> 14 | ... Y36: =Y28 -> 44
B37: Cloud Hosting | C37: 45 | D37: 45 | E37: 45 | F37: 45 | G37: 45 | H37: 45 | I37: 45 | J37: 45 | K37: 45 | L37: 45 | M37: 45 | N37: 45 | O37: 45 | P37: 45 | Q37: 45 | R37: 45 | S37: 45 | T37: 45 | U37: 45 | V37: 45 | W37: 45 | X37: 45 | Y37: 45
B38: Payment Processing | C38: =0.029*C35 -> 3.654 | D38: =0.029*D35 -> 4.06 | E38: =0.029*E35 -> 4.466 | F38: =0.029*F35 -> 4.872 | G38: =0.029*G35 -> 5.278 | H38: =0.029*H35 -> 5.684 | I38: =0.029*I35 -> 5.684 | J38: =0.029*J35 -> 5.684 | ... Y38: =0.029*Y35 -> 17.864
B39: Third-Party APIs | C39: =1*C28 -> 9 | D39: =1*D28 -> 10 | E39: =1*E28 -> 11 | F39: =1*F28 -> 12 | G39: =1*G28 -> 13 | H39: =1*H28 -> 14 | I39: =1*I28 -> 14 | J39: =1*J28 -> 14 | ... Y39: =1*Y28 -> 44
B40: Other Direct Costs | C40: =1*C29 -> 5.4 | D40: =1*D29 -> 6 | E40: =1*E29 -> 6.6 | F40: =1*F29 -> 7.2 | G40: =1*G29 -> 7.8 | H40: =1*H29 -> 8.4 | I40: =1*I29 -> 8.4 | J40: =1*J29 -> 8.4 | ... Y40: =1*Y29 -> 26.4
B41: Total COGS | C41: =SUM(C37:C40) -> 63.054 | D41: =SUM(D37:D40) -> 65.06 | E41: =SUM(E37:E40) -> 67.066 | F41: =SUM(F37:F40) -> 69.072 | G41: =SUM(G37:G40) -> 71.078 | H41: =SUM(H37:H40) -> 73.084 | I41: =SUM(I37:I40) -> 73.084 | J41: =SUM(J37:J40) -> 73.084 | ... Y41: =SUM(Y37:Y40) -> 133.264
A42: Operating Expenses | B42: Customer Acquisition / Marketing | C42: 100 | D42: 100 | E42: 100 | F42: 100 | G42: 100 | H42: 100 | I42: 100 | J42: 100 | K42: 100 | L42: 100 | M42: 100 | N42: 100 | O42: 100 | P42: 100 | Q42: 100 | R42: 100 | S42: 100 | T42: 100 | U42: 100 | V42: 100 | W42: 100 | X42: 100 | Y42: 100
B43: UGC / AI Content | C43: 25 | D43: 25 | E43: 25 | F43: 25 | G43: 25 | H43: 25 | I43: 25 | J43: 25 | K43: 25 | L43: 25 | M43: 25 | N43: 25 | O43: 25 | P43: 25 | Q43: 25 | R43: 25 | S43: 25 | T43: 25 | U43: 25 | V43: 25 | W43: 25 | X43: 25 | Y43: 25
B44: Events | C44: 0 | D44: 0 | E44: 0 | F44: 0 | G44: 0 | H44: 0 | I44: 0 | J44: 0 | K44: 0 | L44: 0 | M44: 0 | N44: 0 | O44: 0 | P44: 0 | Q44: 0 | R44: 0 | S44: 0 | T44: 0 | U44: 0 | V44: 0 | W44: 0 | X44: 0 | Y44: 0
B45: Other S&M / Demos | C45: 25 | D45: 25 | E45: 25 | F45: 25 | G45: 25 | H45: 25 | I45: 25 | J45: 25 | K45: 25 | L45: 25 | M45: 25 | N45: 25 | O45: 25 | P45: 25 | Q45: 25 | R45: 25 | S45: 25 | T45: 25 | U45: 25 | V45: 25 | W45: 25 | X45: 25 | Y45: 25
B46: Development Software | C46: 25 | D46: 25 | E46: 25 | F46: 25 | G46: 25 | H46: 25 | I46: 25 | J46: 25 | K46: 25 | L46: 25 | M46: 25 | N46: 25 | O46: 25 | P46: 25 | Q46: 25 | R46: 25 | S46: 25 | T46: 25 | U46: 25 | V46: 25 | W46: 25 | X46: 25 | Y46: 25
B47: Contractors | C47: 10 | D47: 10 | E47: 10 | F47: 10 | G47: 10 | H47: 10 | I47: 10 | J47: 10 | K47: 10 | L47: 10 | M47: 10 | N47: 10 | O47: 10 | P47: 10 | Q47: 10 | R47: 10 | S47: 10 | T47: 10 | U47: 10 | V47: 10 | W47: 10 | X47: 10 | Y47: 10
B48: Prototypes | C48: 0 | D48: 0 | E48: 0 | F48: 0 | G48: 0 | H48: 0 | I48: 0 | J48: 0 | K48: 0 | L48: 0 | M48: 0 | N48: 0 | O48: 0 | P48: 0 | Q48: 0 | R48: 0 | S48: 0 | T48: 0 | U48: 0 | V48: 0 | W48: 0 | X48: 0 | Y48: 0
B49: Legal | C49: 25 | D49: 25 | E49: 25 | F49: 25 | G49: 25 | H49: 25 | I49: 25 | J49: 25 | K49: 25 | L49: 25 | M49: 25 | N49: 25 | O49: 25 | P49: 25 | Q49: 25 | R49: 25 | S49: 25 | T49: 25 | U49: 25 | V49: 25 | W49: 25 | X49: 25 | Y49: 25
B50: Software / Workspace | C50: 20 | D50: 20 | E50: 20 | F50: 20 | G50: 20 | H50: 20 | I50: 20 | J50: 20 | K50: 20 | L50: 20 | M50: 20 | N50: 20 | O50: 20 | P50: 20 | Q50: 20 | R50: 20 | S50: 20 | T50: 20 | U50: 20 | V50: 20 | W50: 20 | X50: 20 | Y50: 20
B51: Travel | C51: 0 | D51: 0 | E51: 0 | F51: 0 | G51: 0 | H51: 0 | I51: 0 | J51: 0 | K51: 0 | L51: 0 | M51: 0 | N51: 0 | O51: 0 | P51: 0 | Q51: 0 | R51: 0 | S51: 0 | T51: 0 | U51: 0 | V51: 0 | W51: 0 | X51: 0 | Y51: 0
B52: Other G&A | C52: 10 | D52: 10 | E52: 10 | F52: 10 | G52: 10 | H52: 10 | I52: 10 | J52: 10 | K52: 10 | L52: 10 | M52: 10 | N52: 10 | O52: 10 | P52: 10 | Q52: 10 | R52: 10 | S52: 10 | T52: 10 | U52: 10 | V52: 10 | W52: 10 | X52: 10 | Y52: 10
...
